<sdf version='1.7'>
  <world name='default'>
    <light name='sun' type='directional'>
      <cast_shadows>1</cast_shadows>
      <pose>0 0 10 0 -0 0</pose>
      <diffuse>0.8 0.8 0.8 1</diffuse>
      <specular>0.2 0.2 0.2 1</specular>
      <attenuation>
        <range>1000</range>
        <constant>0.9</constant>
        <linear>0.01</linear>
        <quadratic>0.001</quadratic>
      </attenuation>
      <direction>-0.5 0.1 -0.9</direction>
      <spot>
        <inner_angle>0</inner_angle>
        <outer_angle>0</outer_angle>
        <falloff>0</falloff>
      </spot>
    </light>
    <model name='ground_plane'>
      <static>1</static>
      <link name='link'>
        <collision name='collision'>
          <geometry>
            <plane>
              <normal>0 0 1</normal>
              <size>100 100</size>
            </plane>
          </geometry>
          <surface>
            <friction>
              <ode>
                <mu>100</mu>
                <mu2>50</mu2>
              </ode>
              <torsional>
                <ode/>
              </torsional>
            </friction>
            <contact>
              <ode/>
            </contact>
            <bounce/>
          </surface>
          <max_contacts>10</max_contacts>
        </collision>
        <visual name='visual'>
          <cast_shadows>0</cast_shadows>
          <geometry>
            <plane>
              <normal>0 0 1</normal>
              <size>100 100</size>
            </plane>
          </geometry>
          <material>
            <script>
              <uri>file://media/materials/scripts/gazebo.material</uri>
              <name>Gazebo/Grey</name>
            </script>
          </material>
        </visual>
        <self_collide>0</self_collide>
        <enable_wind>0</enable_wind>
        <kinematic>0</kinematic>
      </link>
    </model>
    <gravity>0 0 -9.8</gravity>
    <magnetic_field>6e-06 2.3e-05 -4.2e-05</magnetic_field>
    <atmosphere type='adiabatic'/>
    <physics type='ode'>
      <max_step_size>0.001</max_step_size>
      <real_time_factor>1</real_time_factor>
      <real_time_update_rate>1000</real_time_update_rate>
    </physics>
    <scene>
      <ambient>0.4 0.4 0.4 1</ambient>
      <background>0.7 0.7 0.7 1</background>
      <shadows>1</shadows>
    </scene>
    <audio>
      <device>default</device>
    </audio>
    <wind/>
    <spherical_coordinates>
      <surface_model>EARTH_WGS84</surface_model>
      <latitude_deg>0</latitude_deg>
      <longitude_deg>0</longitude_deg>
      <elevation>0</elevation>
      <heading_deg>0</heading_deg>
    </spherical_coordinates>
    <model name='my_bot'>
      <link name='dummy'>
        <inertial>
          <pose>0.004182 -0 0.02321 0 -0 0</pose>
          <mass>15.4612</mass>
          <inertia>
            <ixx>0.226969</ixx>
            <ixy>-1.09991e-18</ixy>
            <ixz>0.000259952</ixz>
            <iyy>0.514967</iyy>
            <iyz>-4.38387e-20</iyz>
            <izz>0.738186</izz>
          </inertia>
        </inertial>
        <collision name='dummy_fixed_joint_lump__base_link_collision'>
          <pose>0 0 0 0 -0 0</pose>
          <geometry>
            <mesh>
              <scale>0.001 0.001 0.001</scale>
              <uri>file:///home/chaitanya/ros_workspace/install/four_wheel_robot/share/four_wheel_robot/meshes/base_link.stl</uri>
            </mesh>
          </geometry>
          <max_contacts>10</max_contacts>
          <surface>
            <contact>
              <ode/>
            </contact>
            <bounce/>
            <friction>
              <torsional>
                <ode/>
              </torsional>
              <ode/>
            </friction>
          </surface>
        </collision>
        <collision name='dummy_fixed_joint_lump__lidar_link_collision_1'>
          <pose>0.3 0 0.015 0 -0 0</pose>
          <geometry>
            <cylinder>
              <length>0.02</length>
              <radius>0.02</radius>
            </cylinder>
          </geometry>
          <surface>
            <contact>
              <ode/>
            </contact>
            <friction>
              <ode/>
              <torsional>
                <ode/>
              </torsional>
            </friction>
            <bounce/>
          </surface>
          <max_contacts>10</max_contacts>
        </collision>
        <visual name='dummy_fixed_joint_lump__base_link_visual'>
          <pose>0 0 0 0 -0 0</pose>
          <geometry>
            <mesh>
              <scale>0.001 0.001 0.001</scale>
              <uri>file:///home/chaitanya/ros_workspace/install/four_wheel_robot/share/four_wheel_robot/meshes/base_link.stl</uri>
            </mesh>
          </geometry>
        </visual>
        <visual name='dummy_fixed_joint_lump__lidar_link_visual_1'>
          <pose>0.3 0 0.015 0 -0 0</pose>
          <geometry>
            <cylinder>
              <length>0.02</length>
              <radius>0.02</radius>
            </cylinder>
          </geometry>
          <material>
            <script>
              <name>Gazebo/Orange</name>
              <uri>file://media/materials/scripts/gazebo.material</uri>
            </script>
          </material>
        </visual>
        <sensor name='lidar' type='ray'>
          <visualize>1</visualize>
          <update_rate>10</update_rate>
          <ray>
            <scan>
              <horizontal>
                <samples>360</samples>
                <resolution>1</resolution>
                <min_angle>-1.57079</min_angle>
                <max_angle>1.57079</max_angle>
              </horizontal>
              <vertical>
                <samples>1</samples>
                <min_angle>0</min_angle>
                <max_angle>0</max_angle>
              </vertical>
            </scan>
            <range>
              <min>0.3</min>
              <max>12</max>
              <resolution>0.01</resolution>
            </range>
          </ray>
          <plugin name='lidar_controller' filename='libgazebo_ros_ray_sensor.so'>
            <ros>
              <argument>~/out:=scan</argument>
            </ros>
            <output_type>sensor_msgs/LaserScan</output_type>
            <frame_name>lidar_link</frame_name>
          </plugin>
          <pose>0.3 0 0.015 0 -0 0</pose>
        </sensor>
        <self_collide>0</self_collide>
        <enable_wind>0</enable_wind>
        <kinematic>0</kinematic>
      </link>
      <joint name='front_left_joint' type='revolute'>
        <pose relative_to='dummy'>0.2 0.185 0.015 0 -0 0</pose>
        <parent>dummy</parent>
        <child>front_left</child>
        <axis>
          <xyz>0 1 0</xyz>
          <limit>
            <lower>-1e+16</lower>
            <upper>1e+16</upper>
          </limit>
          <dynamics>
            <spring_reference>0</spring_reference>
            <spring_stiffness>0</spring_stiffness>
          </dynamics>
        </axis>
      </joint>
      <link name='front_left'>
        <pose relative_to='front_left_joint'>0 0 0 0 -0 0</pose>
        <inertial>
          <pose>0 -0.002944 0 0 -0 0</pose>
          <mass>0.394974</mass>
          <inertia>
            <ixx>0.000272</ixx>
            <ixy>0</ixy>
            <ixz>0</ixz>
            <iyy>0.000525</iyy>
            <iyz>0</iyz>
            <izz>0.000272</izz>
          </inertia>
        </inertial>
        <collision name='front_left_collision'>
          <pose>-0.2 -0.185 -0.015 0 -0 0</pose>
          <geometry>
            <mesh>
              <scale>0.001 0.001 0.001</scale>
              <uri>file:///home/chaitanya/ros_workspace/install/four_wheel_robot/share/four_wheel_robot/meshes/front_left.stl</uri>
            </mesh>
          </geometry>
          <surface>
            <contact>
              <ode/>
            </contact>
            <friction>
              <ode/>
              <torsional>
                <ode/>
              </torsional>
            </friction>
            <bounce/>
          </surface>
          <max_contacts>10</max_contacts>
        </collision>
        <visual name='front_left_visual'>
          <pose>-0.2 -0.185 -0.015 0 -0 0</pose>
          <geometry>
            <mesh>
              <scale>0.001 0.001 0.001</scale>
              <uri>file:///home/chaitanya/ros_workspace/install/four_wheel_robot/share/four_wheel_robot/meshes/front_left.stl</uri>
            </mesh>
          </geometry>
          <material>
            <script>
              <name>Gazebo/Black</name>
              <uri>file://media/materials/scripts/gazebo.material</uri>
            </script>
          </material>
        </visual>
        <self_collide>1</self_collide>
        <enable_wind>0</enable_wind>
        <kinematic>0</kinematic>
      </link>
      <joint name='front_right_joint' type='revolute'>
        <pose relative_to='dummy'>0.2 -0.185 0.015 0 -0 0</pose>
        <parent>dummy</parent>
        <child>front_right</child>
        <axis>
          <xyz>0 1 0</xyz>
          <limit>
            <lower>-1e+16</lower>
            <upper>1e+16</upper>
          </limit>
          <dynamics>
            <spring_reference>0</spring_reference>
            <spring_stiffness>0</spring_stiffness>
          </dynamics>
        </axis>
      </joint>
      <link name='front_right'>
        <pose relative_to='front_right_joint'>0 0 0 0 -0 0</pose>
        <inertial>
          <pose>0 0.002944 0 0 -0 0</pose>
          <mass>0.394974</mass>
          <inertia>
            <ixx>0.000272</ixx>
            <ixy>0</ixy>
            <ixz>0</ixz>
            <iyy>0.000525</iyy>
            <iyz>0</iyz>
            <izz>0.000272</izz>
          </inertia>
        </inertial>
        <collision name='front_right_collision'>
          <pose>-0.2 0.185 -0.015 0 -0 0</pose>
          <geometry>
            <mesh>
              <scale>0.001 0.001 0.001</scale>
              <uri>file:///home/chaitanya/ros_workspace/install/four_wheel_robot/share/four_wheel_robot/meshes/front_right.stl</uri>
            </mesh>
          </geometry>
          <surface>
            <contact>
              <ode/>
            </contact>
            <friction>
              <ode/>
              <torsional>
                <ode/>
              </torsional>
            </friction>
            <bounce/>
          </surface>
          <max_contacts>10</max_contacts>
        </collision>
        <visual name='front_right_visual'>
          <pose>-0.2 0.185 -0.015 0 -0 0</pose>
          <geometry>
            <mesh>
              <scale>0.001 0.001 0.001</scale>
              <uri>file:///home/chaitanya/ros_workspace/install/four_wheel_robot/share/four_wheel_robot/meshes/front_right.stl</uri>
            </mesh>
          </geometry>
          <material>
            <script>
              <name>Gazebo/Black</name>
              <uri>file://media/materials/scripts/gazebo.material</uri>
            </script>
          </material>
        </visual>
        <self_collide>1</self_collide>
        <enable_wind>0</enable_wind>
        <kinematic>0</kinematic>
      </link>
      <joint name='rear_left_joint' type='revolute'>
        <pose relative_to='dummy'>-0.2 0.185 0.015 0 -0 0</pose>
        <parent>dummy</parent>
        <child>rear_left</child>
        <axis>
          <xyz>0 1 0</xyz>
          <limit>
            <lower>-1e+16</lower>
            <upper>1e+16</upper>
          </limit>
          <dynamics>
            <spring_reference>0</spring_reference>
            <spring_stiffness>0</spring_stiffness>
          </dynamics>
        </axis>
      </joint>
      <link name='rear_left'>
        <pose relative_to='rear_left_joint'>0 0 0 0 -0 0</pose>
        <inertial>
          <pose>-0 -0.002944 -0 0 -0 0</pose>
          <mass>0.394974</mass>
          <inertia>
            <ixx>0.000272</ixx>
            <ixy>0</ixy>
            <ixz>0</ixz>
            <iyy>0.000525</iyy>
            <iyz>0</iyz>
            <izz>0.000272</izz>
          </inertia>
        </inertial>
        <collision name='rear_left_collision'>
          <pose>0.2 -0.185 -0.015 0 -0 0</pose>
          <geometry>
            <mesh>
              <scale>0.001 0.001 0.001</scale>
              <uri>file:///home/chaitanya/ros_workspace/install/four_wheel_robot/share/four_wheel_robot/meshes/rear_left.stl</uri>
            </mesh>
          </geometry>
          <surface>
            <contact>
              <ode/>
            </contact>
            <friction>
              <ode/>
              <torsional>
                <ode/>
              </torsional>
            </friction>
            <bounce/>
          </surface>
          <max_contacts>10</max_contacts>
        </collision>
        <visual name='rear_left_visual'>
          <pose>0.2 -0.185 -0.015 0 -0 0</pose>
          <geometry>
            <mesh>
              <scale>0.001 0.001 0.001</scale>
              <uri>file:///home/chaitanya/ros_workspace/install/four_wheel_robot/share/four_wheel_robot/meshes/rear_left.stl</uri>
            </mesh>
          </geometry>
          <material>
            <script>
              <name>Gazebo/Black</name>
              <uri>file://media/materials/scripts/gazebo.material</uri>
            </script>
          </material>
        </visual>
        <self_collide>1</self_collide>
        <enable_wind>0</enable_wind>
        <kinematic>0</kinematic>
      </link>
      <joint name='rear_right_joint' type='revolute'>
        <pose relative_to='dummy'>-0.2 -0.185 0.015 0 -0 0</pose>
        <parent>dummy</parent>
        <child>rear_right</child>
        <axis>
          <xyz>0 1 0</xyz>
          <limit>
            <lower>-1e+16</lower>
            <upper>1e+16</upper>
          </limit>
          <dynamics>
            <spring_reference>0</spring_reference>
            <spring_stiffness>0</spring_stiffness>
          </dynamics>
        </axis>
      </joint>
      <link name='rear_right'>
        <pose relative_to='rear_right_joint'>0 0 0 0 -0 0</pose>
        <inertial>
          <pose>-0 0.002944 -0 0 -0 0</pose>
          <mass>0.394974</mass>
          <inertia>
            <ixx>0.000272</ixx>
            <ixy>0</ixy>
            <ixz>0</ixz>
            <iyy>0.000525</iyy>
            <iyz>0</iyz>
            <izz>0.000272</izz>
          </inertia>
        </inertial>
        <collision name='rear_right_collision'>
          <pose>0.2 0.185 -0.015 0 -0 0</pose>
          <geometry>
            <mesh>
              <scale>0.001 0.001 0.001</scale>
              <uri>file:///home/chaitanya/ros_workspace/install/four_wheel_robot/share/four_wheel_robot/meshes/rear_right.stl</uri>
            </mesh>
          </geometry>
          <surface>
            <contact>
              <ode/>
            </contact>
            <friction>
              <ode/>
              <torsional>
                <ode/>
              </torsional>
            </friction>
            <bounce/>
          </surface>
          <max_contacts>10</max_contacts>
        </collision>
        <visual name='rear_right_visual'>
          <pose>0.2 0.185 -0.015 0 -0 0</pose>
          <geometry>
            <mesh>
              <scale>0.001 0.001 0.001</scale>
              <uri>file:///home/chaitanya/ros_workspace/install/four_wheel_robot/share/four_wheel_robot/meshes/rear_right.stl</uri>
            </mesh>
          </geometry>
          <material>
            <script>
              <name>Gazebo/Black</name>
              <uri>file://media/materials/scripts/gazebo.material</uri>
            </script>
          </material>
        </visual>
        <self_collide>1</self_collide>
        <enable_wind>0</enable_wind>
        <kinematic>0</kinematic>
      </link>
      <static>0</static>
      <plugin name='object_controller' filename='libgazebo_ros_planar_move.so'>
        <commandTopic>cmd_vel</commandTopic>
        <odometryTopic>odom</odometryTopic>
        <odometryFrame>odom</odometryFrame>
        <odometryRate>20.0</odometryRate>
        <robotBaseFrame>base_link</robotBaseFrame>
      </plugin>
      <pose>0 0 0 0 -0 0</pose>
    </model>
    <model name='cardboard_box'>
      <pose>1.47558 1.22341 0.15 0 -0 0</pose>
      <link name='link'>
        <inertial>
          <mass>2</mass>
          <inertia>
            <ixx>0.0416667</ixx>
            <ixy>0</ixy>
            <ixz>0</ixz>
            <iyy>0.0566667</iyy>
            <iyz>0</iyz>
            <izz>0.0683333</izz>
          </inertia>
          <pose>0 0 0 0 -0 0</pose>
        </inertial>
        <collision name='collision'>
          <geometry>
            <box>
              <size>0.5 0.4 0.3</size>
            </box>
          </geometry>
          <surface>
            <friction>
              <ode>
                <mu>1</mu>
                <mu2>1</mu2>
              </ode>
              <torsional>
                <ode/>
              </torsional>
            </friction>
            <contact>
              <ode>
                <kp>1e+07</kp>
                <kd>1</kd>
                <min_depth>0.001</min_depth>
                <max_vel>0.1</max_vel>
              </ode>
            </contact>
            <bounce/>
          </surface>
          <max_contacts>10</max_contacts>
        </collision>
        <visual name='visual'>
          <pose>0 0 -0.15 0 -0 0</pose>
          <geometry>
            <mesh>
              <uri>model://cardboard_box/meshes/cardboard_box.dae</uri>
              <scale>1.25932 1.00745 0.755591</scale>
            </mesh>
          </geometry>
        </visual>
        <self_collide>0</self_collide>
        <enable_wind>0</enable_wind>
        <kinematic>0</kinematic>
      </link>
    </model>
    <model name='Construction Barrel'>
      <link name='link'>
        <inertial>
          <pose>0 0 0.4 0 -0 0</pose>
          <mass>500</mass>
          <inertia>
            <ixx>51.2096</ixx>
            <iyy>51.2096</iyy>
            <izz>25</izz>
            <ixy>0</ixy>
            <ixz>0</ixz>
            <iyz>0</iyz>
          </inertia>
        </inertial>
        <collision name='collision'>
          <geometry>
            <mesh>
              <uri>model://construction_barrel/meshes/construction_barrel.dae</uri>
            </mesh>
          </geometry>
          <max_contacts>10</max_contacts>
          <surface>
            <contact>
              <ode/>
            </contact>
            <bounce/>
            <friction>
              <torsional>
                <ode/>
              </torsional>
              <ode/>
            </friction>
          </surface>
        </collision>
        <visual name='visual'>
          <geometry>
            <mesh>
              <uri>model://construction_barrel/meshes/construction_barrel.dae</uri>
            </mesh>
          </geometry>
        </visual>
        <self_collide>0</self_collide>
        <enable_wind>0</enable_wind>
        <kinematic>0</kinematic>
      </link>
      <pose>2.21613 -2.00284 0 0 -0 0</pose>
    </model>
    <model name='Construction Cone'>
      <link name='link'>
        <collision name='collision'>
          <geometry>
            <mesh>
              <scale>10 10 10</scale>
              <uri>model://construction_cone/meshes/construction_cone.dae</uri>
            </mesh>
          </geometry>
          <max_contacts>10</max_contacts>
          <surface>
            <contact>
              <ode/>
            </contact>
            <bounce/>
            <friction>
              <torsional>
                <ode/>
              </torsional>
              <ode/>
            </friction>
          </surface>
        </collision>
        <visual name='visual'>
          <geometry>
            <mesh>
              <scale>10 10 10</scale>
              <uri>model://construction_cone/meshes/construction_cone.dae</uri>
            </mesh>
          </geometry>
        </visual>
        <self_collide>0</self_collide>
        <inertial>
          <pose>0 0 0 0 -0 0</pose>
          <inertia>
            <ixx>1</ixx>
            <ixy>0</ixy>
            <ixz>0</ixz>
            <iyy>1</iyy>
            <iyz>0</iyz>
            <izz>1</izz>
          </inertia>
          <mass>1</mass>
        </inertial>
        <enable_wind>0</enable_wind>
        <kinematic>0</kinematic>
      </link>
      <pose>0.918806 -2.57451 0 0 -0 0</pose>
    </model>
    <state world_name='default'>
      <sim_time>267 432000000</sim_time>
      <real_time>268 705129653</real_time>
      <wall_time>1709046519 51239247</wall_time>
      <iterations>267432</iterations>
      <model name='Construction Barrel'>
        <pose>2.2161 -2.00285 -3e-06 -4e-06 -5e-06 -8e-06</pose>
        <scale>1 1 1</scale>
        <link name='link'>
          <pose>2.2161 -2.00285 -3e-06 -4e-06 -5e-06 -8e-06</pose>
          <velocity>0 0 0 0 -0 0</velocity>
          <acceleration>-2.59608 0.696298 -6.34585 -1.73182 -0.189437 0.006475</acceleration>
          <wrench>-1298.04 348.149 -3172.92 0 -0 0</wrench>
        </link>
      </model>
      <model name='Construction Cone'>
        <pose>0.918806 -2.57451 0 -0 -0 -0</pose>
        <scale>1 1 1</scale>
        <link name='link'>
          <pose>0.918806 -2.57451 0 -0 -0 -0</pose>
          <velocity>0 0 0 0 -0 0</velocity>
          <acceleration>-0 -0 19.3183 1.39427 -0.405542 -0</acceleration>
          <wrench>-0 -0 19.3183 0 -0 0</wrench>
        </link>
      </model>
      <model name='cardboard_box'>
        <pose>1.47558 1.22341 0.149 0 -0 0</pose>
        <scale>1 1 1</scale>
        <link name='link'>
          <pose>1.47558 1.22341 0.149 0 -0 0</pose>
          <velocity>0 0 0 0 -0 0</velocity>
          <acceleration>-0 1.9e-05 -0 -0.000128 -2e-06 0</acceleration>
          <wrench>-1e-06 3.8e-05 -1e-06 0 -0 0</wrench>
        </link>
      </model>
      <model name='ground_plane'>
        <pose>0 0 0 0 -0 0</pose>
        <scale>1 1 1</scale>
        <link name='link'>
          <pose>0 0 0 0 -0 0</pose>
          <velocity>0 0 0 0 -0 0</velocity>
          <acceleration>0 0 0 0 -0 0</acceleration>
          <wrench>0 0 0 0 -0 0</wrench>
        </link>
      </model>
      <model name='my_bot'>
        <pose>-0.000396 0.001668 0.029947 -2.2e-05 -5e-06 0.089892</pose>
        <scale>1 1 1</scale>
        <link name='dummy'>
          <pose>-0.000396 0.001668 0.029947 -2.2e-05 -5e-06 0.089892</pose>
          <velocity>0.001104 0.00033 -0.003215 -0.020624 -0.006984 -0.000845</velocity>
          <acceleration>-0.029086 0.080747 -9.53304 -2.91818 1.2078 -0.375061</acceleration>
          <wrench>-0.4497 1.24845 -147.392 0 -0 0</wrench>
        </link>
        <link name='front_left'>
          <pose>0.182189 0.203875 0.044944 -4.5e-05 0.00015 0.089891</pose>
          <velocity>0.001152 0.000528 -0.005928 -0.0173 0.020905 -0.000566</velocity>
          <acceleration>0.15536 0.096238 -10.9949 -1.58808 -1.05025 -2.14433</acceleration>
          <wrench>0.061363 0.038012 -4.34271 0 -0 0</wrench>
        </link>
        <link name='front_right'>
          <pose>0.215403 -0.164631 0.044954 -3.5e-05 0.096697 0.089887</pose>
          <velocity>0.001046 0.000353 0.001427 -0.019852 0.019393 -0.000473</velocity>
          <acceleration>0.132167 -0.113483 -8.67728 3.07488 -1.26628 0.126472</acceleration>
          <wrench>0.052202 -0.044823 -3.4273 0 -0 0</wrench>
        </link>
        <link name='rear_left'>
          <pose>-0.216196 0.167966 0.044943 -4.6e-05 -0.096394 0.089894</pose>
          <velocity>0.001018 0.000965 -0.008435 -0.017005 0.020661 -0.000181</velocity>
          <acceleration>0.091173 0.06156 -9.02327 3.03721 0.405138 -1.08198</acceleration>
          <wrench>0.036011 0.024315 -3.56396 0 -0 0</wrench>
        </link>
        <link name='rear_right'>
          <pose>-0.182981 -0.200539 0.044949 -1.3e-05 0.000271 0.0899</pose>
          <velocity>0.000829 0.000855 -7.7e-05 -0.018977 0.018036 -0.002397</velocity>
          <acceleration>-0.037815 -0.048203 -9.39623 1.05468 -1.09957 -1.11705</acceleration>
          <wrench>-0.014936 -0.019039 -3.71127 0 -0 0</wrench>
        </link>
      </model>
      <light name='sun'>
        <pose>0 0 10 0 -0 0</pose>
      </light>
    </state>
    <gui fullscreen='0'>
      <camera name='user_camera'>
        <pose>-4.15386 -14.6782 9.57054 0 0.499642 0.768198</pose>
        <view_controller>orbit</view_controller>
        <projection_type>perspective</projection_type>
      </camera>
    </gui>
  </world>
</sdf>
