<sdf version='1.7'>
  <world name='default'>
    <light name='sun' type='directional'>
      <cast_shadows>1</cast_shadows>
      <pose>0 0 10 0 -0 0</pose>
      <diffuse>0.8 0.8 0.8 1</diffuse>
      <specular>0.2 0.2 0.2 1</specular>
      <attenuation>
        <range>1000</range>
        <constant>0.9</constant>
        <linear>0.01</linear>
        <quadratic>0.001</quadratic>
      </attenuation>
      <direction>-0.5 0.1 -0.9</direction>
      <spot>
        <inner_angle>0</inner_angle>
        <outer_angle>0</outer_angle>
        <falloff>0</falloff>
      </spot>
    </light>
    <model name='ground_plane'>
      <static>1</static>
      <link name='link'>
        <collision name='collision'>
          <geometry>
            <plane>
              <normal>0 0 1</normal>
              <size>100 100</size>
            </plane>
          </geometry>
          <surface>
            <friction>
              <ode>
                <mu>100</mu>
                <mu2>50</mu2>
              </ode>
              <torsional>
                <ode/>
              </torsional>
            </friction>
            <contact>
              <ode/>
            </contact>
            <bounce/>
          </surface>
          <max_contacts>10</max_contacts>
        </collision>
        <visual name='visual'>
          <cast_shadows>0</cast_shadows>
          <geometry>
            <plane>
              <normal>0 0 1</normal>
              <size>100 100</size>
            </plane>
          </geometry>
          <material>
            <script>
              <uri>file://media/materials/scripts/gazebo.material</uri>
              <name>Gazebo/Grey</name>
            </script>
          </material>
        </visual>
        <self_collide>0</self_collide>
        <enable_wind>0</enable_wind>
        <kinematic>0</kinematic>
      </link>
    </model>
    <gravity>0 0 -9.8</gravity>
    <magnetic_field>6e-06 2.3e-05 -4.2e-05</magnetic_field>
    <atmosphere type='adiabatic'/>
    <physics type='ode'>
      <max_step_size>0.001</max_step_size>
      <real_time_factor>1</real_time_factor>
      <real_time_update_rate>1000</real_time_update_rate>
    </physics>
    <scene>
      <ambient>0.4 0.4 0.4 1</ambient>
      <background>0.7 0.7 0.7 1</background>
      <shadows>1</shadows>
    </scene>
    <audio>
      <device>default</device>
    </audio>
    <wind/>
    <spherical_coordinates>
      <surface_model>EARTH_WGS84</surface_model>
      <latitude_deg>0</latitude_deg>
      <longitude_deg>0</longitude_deg>
      <elevation>0</elevation>
      <heading_deg>0</heading_deg>
    </spherical_coordinates>
    <model name='mobile_manipulator'>
      <link name='ground'>
        <inertial>
          <pose>-0.000627 -0.836396 0.647826 0 -0 0</pose>
          <mass>471.941</mass>
          <inertia>
            <ixx>178.928</ixx>
            <ixy>0.796035</ixy>
            <ixz>0.0658091</ixz>
            <iyy>64.8136</iyy>
            <iyz>15.559</iyz>
            <izz>162.997</izz>
          </inertia>
        </inertial>
        <collision name='ground_fixed_joint_lump__cart_collision'>
          <pose>0 0 0.18 0 -0 0</pose>
          <geometry>
            <mesh>
              <scale>0.001 0.001 0.001</scale>
              <uri>file:///home/chaitanya/ros_workspace/install/mobile_manipulator/share/mobile_manipulator/meshes/cart.stl</uri>
            </mesh>
          </geometry>
          <surface>
            <contact>
              <ode/>
            </contact>
            <friction>
              <ode/>
              <torsional>
                <ode/>
              </torsional>
            </friction>
            <bounce/>
          </surface>
          <max_contacts>10</max_contacts>
        </collision>
        <collision name='ground_fixed_joint_lump__basket_link_collision_1'>
          <pose>0 0 0.18 0 -0 0</pose>
          <geometry>
            <mesh>
              <scale>0.001 0.001 0.001</scale>
              <uri>file:///home/chaitanya/ros_workspace/install/mobile_manipulator/share/mobile_manipulator/meshes/basket.stl</uri>
            </mesh>
          </geometry>
          <surface>
            <contact>
              <ode/>
            </contact>
            <friction>
              <ode/>
              <torsional>
                <ode/>
              </torsional>
            </friction>
            <bounce/>
          </surface>
          <max_contacts>10</max_contacts>
        </collision>
        <collision name='ground_fixed_joint_lump__front_lidar_collision_2'>
          <pose>0 0 0.18 0 -0 0</pose>
          <geometry>
            <mesh>
              <scale>0.001 0.001 0.001</scale>
              <uri>file:///home/chaitanya/ros_workspace/install/mobile_manipulator/share/mobile_manipulator/meshes/lidar_front.stl</uri>
            </mesh>
          </geometry>
          <surface>
            <contact>
              <ode/>
            </contact>
            <friction>
              <ode/>
              <torsional>
                <ode/>
              </torsional>
            </friction>
            <bounce/>
          </surface>
          <max_contacts>10</max_contacts>
        </collision>
        <collision name='ground_fixed_joint_lump__rear_lidar_collision_3'>
          <pose>0 0 0.18 0 -0 0</pose>
          <geometry>
            <mesh>
              <scale>0.001 0.001 0.001</scale>
              <uri>file:///home/chaitanya/ros_workspace/install/mobile_manipulator/share/mobile_manipulator/meshes/lidar_rear.stl</uri>
            </mesh>
          </geometry>
          <surface>
            <contact>
              <ode/>
            </contact>
            <friction>
              <ode/>
              <torsional>
                <ode/>
              </torsional>
            </friction>
            <bounce/>
          </surface>
          <max_contacts>10</max_contacts>
        </collision>
        <visual name='ground_fixed_joint_lump__cart_visual'>
          <pose>0 0 0.18 0 -0 0</pose>
          <geometry>
            <mesh>
              <scale>0.001 0.001 0.001</scale>
              <uri>file:///home/chaitanya/ros_workspace/install/mobile_manipulator/share/mobile_manipulator/meshes/cart.stl</uri>
            </mesh>
          </geometry>
          <material>
            <script>
              <name>Gazebo/Grey</name>
              <uri>file://media/materials/scripts/gazebo.material</uri>
            </script>
          </material>
        </visual>
        <visual name='ground_fixed_joint_lump__basket_link_visual_1'>
          <pose>0 0 0.18 0 -0 0</pose>
          <geometry>
            <mesh>
              <scale>0.001 0.001 0.001</scale>
              <uri>file:///home/chaitanya/ros_workspace/install/mobile_manipulator/share/mobile_manipulator/meshes/basket.stl</uri>
            </mesh>
          </geometry>
          <material>
            <script>
              <name>Gazebo/Yellow</name>
              <uri>file://media/materials/scripts/gazebo.material</uri>
            </script>
          </material>
        </visual>
        <visual name='ground_fixed_joint_lump__front_camera_link_visual_2'>
          <pose>0 -0.055223 0.88 0 -0 0</pose>
          <geometry>
            <box>
              <size>0.06 0.01 0.03</size>
            </box>
          </geometry>
          <material>
            <script>
              <name>Gazebo/Black</name>
              <uri>file://media/materials/scripts/gazebo.material</uri>
            </script>
          </material>
        </visual>
        <visual name='ground_fixed_joint_lump__left_camera_link_visual_3'>
          <pose>-0.31 -0.765223 0.88 0 -0 0</pose>
          <geometry>
            <box>
              <size>0.01 0.06 0.03</size>
            </box>
          </geometry>
          <material>
            <script>
              <name>Gazebo/Black</name>
              <uri>file://media/materials/scripts/gazebo.material</uri>
            </script>
          </material>
        </visual>
        <visual name='ground_fixed_joint_lump__right_camera_link_visual_4'>
          <pose>0.31 -0.765223 0.88 0 -0 0</pose>
          <geometry>
            <box>
              <size>0.01 0.06 0.03</size>
            </box>
          </geometry>
          <material>
            <script>
              <name>Gazebo/Black</name>
              <uri>file://media/materials/scripts/gazebo.material</uri>
            </script>
          </material>
        </visual>
        <visual name='ground_fixed_joint_lump__front_lidar_visual_5'>
          <pose>0 0 0.18 0 -0 0</pose>
          <geometry>
            <mesh>
              <scale>0.001 0.001 0.001</scale>
              <uri>file:///home/chaitanya/ros_workspace/install/mobile_manipulator/share/mobile_manipulator/meshes/lidar_front.stl</uri>
            </mesh>
          </geometry>
          <material>
            <script>
              <name>Gazebo/Red</name>
              <uri>file://media/materials/scripts/gazebo.material</uri>
            </script>
          </material>
        </visual>
        <visual name='ground_fixed_joint_lump__rear_lidar_visual_6'>
          <pose>0 0 0.18 0 -0 0</pose>
          <geometry>
            <mesh>
              <scale>0.001 0.001 0.001</scale>
              <uri>file:///home/chaitanya/ros_workspace/install/mobile_manipulator/share/mobile_manipulator/meshes/lidar_rear.stl</uri>
            </mesh>
          </geometry>
          <material>
            <script>
              <name>Gazebo/Red</name>
              <uri>file://media/materials/scripts/gazebo.material</uri>
            </script>
          </material>
        </visual>
        <sensor name='front_camera' type='depth'>
          <visualize>1</visualize>
          <update_rate>10</update_rate>
          <camera>
            <pose>0 0 0 0 -0 1.57</pose>
            <horizontal_fov>1.8</horizontal_fov>
            <image>
              <width>800</width>
              <height>480</height>
              <format>B8G8R8</format>
            </image>
            <clip>
              <near>0.05</near>
              <far>8</far>
            </clip>
          </camera>
          <plugin name='front_camera_controller' filename='libgazebo_ros_camera.so'>
            <frame_name>front_camera_link_optical</frame_name>
          </plugin>
          <pose>0 -0.055223 0.88 0 -0 0</pose>
        </sensor>
        <sensor name='left_camera' type='depth'>
          <visualize>1</visualize>
          <update_rate>10</update_rate>
          <camera>
            <pose>0 0 0 0 -0 3.14</pose>
            <horizontal_fov>1.8</horizontal_fov>
            <image>
              <width>800</width>
              <height>480</height>
              <format>B8G8R8</format>
            </image>
            <clip>
              <near>0.05</near>
              <far>8</far>
            </clip>
          </camera>
          <plugin name='left_camera_controller' filename='libgazebo_ros_camera.so'>
            <frame_name>left_camera_link_optical</frame_name>
          </plugin>
          <pose>-0.31 -0.765223 0.88 0 -0 0</pose>
        </sensor>
        <sensor name='right_camera' type='depth'>
          <visualize>1</visualize>
          <update_rate>10</update_rate>
          <camera>
            <pose>0 0 0 0 -0 0</pose>
            <horizontal_fov>1.8</horizontal_fov>
            <image>
              <width>800</width>
              <height>480</height>
              <format>B8G8R8</format>
            </image>
            <clip>
              <near>0.05</near>
              <far>8</far>
            </clip>
          </camera>
          <plugin name='right_camera_controller' filename='libgazebo_ros_camera.so'>
            <frame_name>right_camera_link_optical</frame_name>
          </plugin>
          <pose>0.31 -0.765223 0.88 0 -0 0</pose>
        </sensor>
        <sensor name='front_lidar' type='ray'>
          <visualize>1</visualize>
          <update_rate>10</update_rate>
          <ray>
            <scan>
              <horizontal>
                <samples>360</samples>
                <resolution>1</resolution>
                <min_angle>0.2</min_angle>
                <max_angle>2.9</max_angle>
              </horizontal>
              <vertical>
                <samples>1</samples>
                <min_angle>0</min_angle>
                <max_angle>0</max_angle>
              </vertical>
            </scan>
            <range>
              <min>0.3</min>
              <max>6</max>
              <resolution>0.01</resolution>
            </range>
          </ray>
          <plugin name='lidar_controller_front' filename='libgazebo_ros_ray_sensor.so'>
            <ros>
              <argument>--ros-args --remap ~/out:=front_lidar_scan</argument>
            </ros>
            <output_type>sensor_msgs/LaserScan</output_type>
            <frame_name>front_lidar</frame_name>
          </plugin>
          <pose>0 -0.115682 0.1 0 -0 0</pose>
        </sensor>
        <sensor name='rear_lidar' type='ray'>
          <visualize>1</visualize>
          <update_rate>10</update_rate>
          <ray>
            <scan>
              <horizontal>
                <samples>360</samples>
                <resolution>1</resolution>
                <min_angle>-0.2</min_angle>
                <max_angle>-2.9</max_angle>
              </horizontal>
              <vertical>
                <samples>1</samples>
                <min_angle>0</min_angle>
                <max_angle>0</max_angle>
              </vertical>
            </scan>
            <range>
              <min>0.3</min>
              <max>6</max>
              <resolution>0.01</resolution>
            </range>
          </ray>
          <plugin name='lidar_controller_rear' filename='libgazebo_ros_ray_sensor.so'>
            <ros>
              <argument>--ros-args --remap ~/out:=rear_lidar_scan</argument>
            </ros>
            <output_type>sensor_msgs/LaserScan</output_type>
            <frame_name>rear_lidar</frame_name>
          </plugin>
          <pose>0 -1.27432 0.1 0 -0 0</pose>
        </sensor>
        <self_collide>0</self_collide>
        <enable_wind>0</enable_wind>
        <kinematic>0</kinematic>
      </link>
      <joint name='front_left_wheel_joint' type='revolute'>
        <pose relative_to='ground'>-0.3 -0.163182 0.08 0 -0 0</pose>
        <parent>ground</parent>
        <child>front_left_wheel</child>
        <axis>
          <xyz>-1 0 0</xyz>
          <limit>
            <lower>-1e+16</lower>
            <upper>1e+16</upper>
          </limit>
          <dynamics>
            <spring_reference>0</spring_reference>
            <spring_stiffness>0</spring_stiffness>
          </dynamics>
        </axis>
      </joint>
      <link name='front_left_wheel'>
        <pose relative_to='front_left_wheel_joint'>0 0 0 0 -0 0</pose>
        <inertial>
          <pose>0.002739 0 0 0 -0 0</pose>
          <mass>2.98517</mass>
          <inertia>
            <ixx>0.012239</ixx>
            <ixy>0</ixy>
            <ixz>0</ixz>
            <iyy>0.006838</iyy>
            <iyz>0</iyz>
            <izz>0.006838</izz>
          </inertia>
        </inertial>
        <collision name='front_left_wheel_collision'>
          <pose>0.3 0.163182 0.1 0 -0 0</pose>
          <geometry>
            <mesh>
              <scale>0.001 0.001 0.001</scale>
              <uri>file:///home/chaitanya/ros_workspace/install/mobile_manipulator/share/mobile_manipulator/meshes/wheel_3.stl</uri>
            </mesh>
          </geometry>
          <surface>
            <contact>
              <ode/>
            </contact>
            <friction>
              <ode>
                <mu>0.001</mu>
                <mu2>0.001</mu2>
              </ode>
              <torsional>
                <ode/>
              </torsional>
            </friction>
            <bounce/>
          </surface>
          <max_contacts>10</max_contacts>
        </collision>
        <visual name='front_left_wheel_visual'>
          <pose>0.3 0.163182 0.1 0 -0 0</pose>
          <geometry>
            <mesh>
              <scale>0.001 0.001 0.001</scale>
              <uri>file:///home/chaitanya/ros_workspace/install/mobile_manipulator/share/mobile_manipulator/meshes/wheel_3.stl</uri>
            </mesh>
          </geometry>
          <material>
            <script>
              <name>Gazebo/Black</name>
              <uri>file://media/materials/scripts/gazebo.material</uri>
            </script>
          </material>
        </visual>
        <self_collide>0</self_collide>
        <enable_wind>0</enable_wind>
        <kinematic>0</kinematic>
      </link>
      <joint name='front_right_wheel_joint' type='revolute'>
        <pose relative_to='ground'>0.3 -0.163182 0.08 0 -0 0</pose>
        <parent>ground</parent>
        <child>front_right_wheel</child>
        <axis>
          <xyz>-1 0 0</xyz>
          <limit>
            <lower>-1e+16</lower>
            <upper>1e+16</upper>
          </limit>
          <dynamics>
            <spring_reference>0</spring_reference>
            <spring_stiffness>0</spring_stiffness>
          </dynamics>
        </axis>
      </joint>
      <link name='front_right_wheel'>
        <pose relative_to='front_right_wheel_joint'>0 0 0 0 -0 0</pose>
        <inertial>
          <pose>-0.002739 0 0 0 -0 0</pose>
          <mass>2.98517</mass>
          <inertia>
            <ixx>0.012239</ixx>
            <ixy>0</ixy>
            <ixz>0</ixz>
            <iyy>0.006838</iyy>
            <iyz>0</iyz>
            <izz>0.006838</izz>
          </inertia>
        </inertial>
        <collision name='front_right_wheel_collision'>
          <pose>-0.3 0.163182 0.1 0 -0 0</pose>
          <geometry>
            <mesh>
              <scale>0.001 0.001 0.001</scale>
              <uri>file:///home/chaitanya/ros_workspace/install/mobile_manipulator/share/mobile_manipulator/meshes/wheel_1.stl</uri>
            </mesh>
          </geometry>
          <surface>
            <contact>
              <ode/>
            </contact>
            <friction>
              <ode>
                <mu>0.001</mu>
                <mu2>0.001</mu2>
              </ode>
              <torsional>
                <ode/>
              </torsional>
            </friction>
            <bounce/>
          </surface>
          <max_contacts>10</max_contacts>
        </collision>
        <visual name='front_right_wheel_visual'>
          <pose>-0.3 0.163182 0.1 0 -0 0</pose>
          <geometry>
            <mesh>
              <scale>0.001 0.001 0.001</scale>
              <uri>file:///home/chaitanya/ros_workspace/install/mobile_manipulator/share/mobile_manipulator/meshes/wheel_1.stl</uri>
            </mesh>
          </geometry>
          <material>
            <script>
              <name>Gazebo/Black</name>
              <uri>file://media/materials/scripts/gazebo.material</uri>
            </script>
          </material>
        </visual>
        <self_collide>0</self_collide>
        <enable_wind>0</enable_wind>
        <kinematic>0</kinematic>
      </link>
      <joint name='rear_left_wheel_joint' type='revolute'>
        <pose relative_to='ground'>-0.3 -1.22682 0.08 0 -0 0</pose>
        <parent>ground</parent>
        <child>rear_left_wheel</child>
        <axis>
          <xyz>-1 0 0</xyz>
          <limit>
            <lower>-1e+16</lower>
            <upper>1e+16</upper>
          </limit>
          <dynamics>
            <spring_reference>0</spring_reference>
            <spring_stiffness>0</spring_stiffness>
          </dynamics>
        </axis>
      </joint>
      <link name='rear_left_wheel'>
        <pose relative_to='rear_left_wheel_joint'>0 0 0 0 -0 0</pose>
        <inertial>
          <pose>0.002739 -0 0 0 -0 0</pose>
          <mass>2.98517</mass>
          <inertia>
            <ixx>0.012239</ixx>
            <ixy>0</ixy>
            <ixz>0</ixz>
            <iyy>0.006838</iyy>
            <iyz>0</iyz>
            <izz>0.006838</izz>
          </inertia>
        </inertial>
        <collision name='rear_left_wheel_collision'>
          <pose>0.3 1.22682 0.1 0 -0 0</pose>
          <geometry>
            <mesh>
              <scale>0.001 0.001 0.001</scale>
              <uri>file:///home/chaitanya/ros_workspace/install/mobile_manipulator/share/mobile_manipulator/meshes/wheel_4.stl</uri>
            </mesh>
          </geometry>
          <surface>
            <contact>
              <ode/>
            </contact>
            <friction>
              <ode>
                <mu>0.001</mu>
                <mu2>0.001</mu2>
              </ode>
              <torsional>
                <ode/>
              </torsional>
            </friction>
            <bounce/>
          </surface>
          <max_contacts>10</max_contacts>
        </collision>
        <visual name='rear_left_wheel_visual'>
          <pose>0.3 1.22682 0.1 0 -0 0</pose>
          <geometry>
            <mesh>
              <scale>0.001 0.001 0.001</scale>
              <uri>file:///home/chaitanya/ros_workspace/install/mobile_manipulator/share/mobile_manipulator/meshes/wheel_4.stl</uri>
            </mesh>
          </geometry>
          <material>
            <script>
              <name>Gazebo/Black</name>
              <uri>file://media/materials/scripts/gazebo.material</uri>
            </script>
          </material>
        </visual>
        <self_collide>0</self_collide>
        <enable_wind>0</enable_wind>
        <kinematic>0</kinematic>
      </link>
      <joint name='rear_right_wheel_joint' type='revolute'>
        <pose relative_to='ground'>0.3 -1.22682 0.08 0 -0 0</pose>
        <parent>ground</parent>
        <child>rear_right_wheel</child>
        <axis>
          <xyz>-1 0 0</xyz>
          <limit>
            <lower>-1e+16</lower>
            <upper>1e+16</upper>
          </limit>
          <dynamics>
            <spring_reference>0</spring_reference>
            <spring_stiffness>0</spring_stiffness>
          </dynamics>
        </axis>
      </joint>
      <link name='rear_right_wheel'>
        <pose relative_to='rear_right_wheel_joint'>0 0 0 0 -0 0</pose>
        <inertial>
          <pose>-0.002739 -0 0 0 -0 0</pose>
          <mass>2.98517</mass>
          <inertia>
            <ixx>0.012239</ixx>
            <ixy>0</ixy>
            <ixz>0</ixz>
            <iyy>0.006838</iyy>
            <iyz>0</iyz>
            <izz>0.006838</izz>
          </inertia>
        </inertial>
        <collision name='rear_right_wheel_collision'>
          <pose>-0.3 1.22682 0.1 0 -0 0</pose>
          <geometry>
            <mesh>
              <scale>0.001 0.001 0.001</scale>
              <uri>file:///home/chaitanya/ros_workspace/install/mobile_manipulator/share/mobile_manipulator/meshes/wheel_2.stl</uri>
            </mesh>
          </geometry>
          <surface>
            <contact>
              <ode/>
            </contact>
            <friction>
              <ode>
                <mu>0.001</mu>
                <mu2>0.001</mu2>
              </ode>
              <torsional>
                <ode/>
              </torsional>
            </friction>
            <bounce/>
          </surface>
          <max_contacts>10</max_contacts>
        </collision>
        <visual name='rear_right_wheel_visual'>
          <pose>-0.3 1.22682 0.1 0 -0 0</pose>
          <geometry>
            <mesh>
              <scale>0.001 0.001 0.001</scale>
              <uri>file:///home/chaitanya/ros_workspace/install/mobile_manipulator/share/mobile_manipulator/meshes/wheel_2.stl</uri>
            </mesh>
          </geometry>
          <material>
            <script>
              <name>Gazebo/Black</name>
              <uri>file://media/materials/scripts/gazebo.material</uri>
            </script>
          </material>
        </visual>
        <self_collide>0</self_collide>
        <enable_wind>0</enable_wind>
        <kinematic>0</kinematic>
      </link>
      <pose>0 0 0 0 -0 0</pose>
    </model>
    <model name='Untitled'>
      <pose>0.26 -0.99 0 0 -0 0</pose>
      <link name='Wall_1'>
        <collision name='Wall_1_Collision'>
          <geometry>
            <box>
              <size>3.75 0.15 2.5</size>
            </box>
          </geometry>
          <pose>0 0 1.25 0 -0 0</pose>
          <max_contacts>10</max_contacts>
          <surface>
            <contact>
              <ode/>
            </contact>
            <bounce/>
            <friction>
              <torsional>
                <ode/>
              </torsional>
              <ode/>
            </friction>
          </surface>
        </collision>
        <visual name='Wall_1_Visual'>
          <pose>0 0 1.25 0 -0 0</pose>
          <geometry>
            <box>
              <size>3.75 0.15 2.5</size>
            </box>
          </geometry>
          <material>
            <script>
              <uri>file://media/materials/scripts/gazebo.material</uri>
              <name>Gazebo/Grey</name>
            </script>
            <ambient>1 1 1 1</ambient>
          </material>
          <meta>
            <layer>0</layer>
          </meta>
        </visual>
        <pose>0 -2.8 0 0 -0 0</pose>
        <self_collide>0</self_collide>
        <enable_wind>0</enable_wind>
        <kinematic>0</kinematic>
      </link>
      <link name='Wall_2'>
        <collision name='Wall_2_Collision'>
          <geometry>
            <box>
              <size>5.75 0.15 2.5</size>
            </box>
          </geometry>
          <pose>0 0 1.25 0 -0 0</pose>
          <max_contacts>10</max_contacts>
          <surface>
            <contact>
              <ode/>
            </contact>
            <bounce/>
            <friction>
              <torsional>
                <ode/>
              </torsional>
              <ode/>
            </friction>
          </surface>
        </collision>
        <visual name='Wall_2_Visual'>
          <pose>0 0 1.25 0 -0 0</pose>
          <geometry>
            <box>
              <size>5.75 0.15 2.5</size>
            </box>
          </geometry>
          <material>
            <script>
              <uri>file://media/materials/scripts/gazebo.material</uri>
              <name>Gazebo/Grey</name>
            </script>
            <ambient>1 1 1 1</ambient>
          </material>
          <meta>
            <layer>0</layer>
          </meta>
        </visual>
        <pose>1.8 0 0 0 -0 1.5708</pose>
        <self_collide>0</self_collide>
        <enable_wind>0</enable_wind>
        <kinematic>0</kinematic>
      </link>
      <link name='Wall_3'>
        <pose>0 2.8 0 0 -0 3.14159</pose>
        <visual name='Wall_3_Visual_0'>
          <pose>-1.24455 0 1.25 0 -0 0</pose>
          <geometry>
            <box>
              <size>1.26089 0.15 2.5</size>
            </box>
          </geometry>
          <material>
            <script>
              <uri>file://media/materials/scripts/gazebo.material</uri>
              <name>Gazebo/Grey</name>
            </script>
            <ambient>1 1 1 1</ambient>
          </material>
          <meta>
            <layer>0</layer>
          </meta>
        </visual>
        <collision name='Wall_3_Collision_0'>
          <geometry>
            <box>
              <size>1.26089 0.15 2.5</size>
            </box>
          </geometry>
          <pose>-1.24455 0 1.25 0 -0 0</pose>
          <max_contacts>10</max_contacts>
          <surface>
            <contact>
              <ode/>
            </contact>
            <bounce/>
            <friction>
              <torsional>
                <ode/>
              </torsional>
              <ode/>
            </friction>
          </surface>
        </collision>
        <visual name='Wall_3_Visual_1'>
          <pose>1.08045 0 1.25 0 -0 0</pose>
          <geometry>
            <box>
              <size>1.58911 0.15 2.5</size>
            </box>
          </geometry>
          <material>
            <script>
              <uri>file://media/materials/scripts/gazebo.material</uri>
              <name>Gazebo/Grey</name>
            </script>
            <ambient>1 1 1 1</ambient>
          </material>
          <meta>
            <layer>0</layer>
          </meta>
        </visual>
        <collision name='Wall_3_Collision_1'>
          <geometry>
            <box>
              <size>1.58911 0.15 2.5</size>
            </box>
          </geometry>
          <pose>1.08045 0 1.25 0 -0 0</pose>
          <max_contacts>10</max_contacts>
          <surface>
            <contact>
              <ode/>
            </contact>
            <bounce/>
            <friction>
              <torsional>
                <ode/>
              </torsional>
              <ode/>
            </friction>
          </surface>
        </collision>
        <visual name='Wall_3_Visual_2'>
          <pose>-0.164106 0 2.25 0 -0 0</pose>
          <geometry>
            <box>
              <size>0.9 0.15 0.5</size>
            </box>
          </geometry>
          <material>
            <script>
              <uri>file://media/materials/scripts/gazebo.material</uri>
              <name>Gazebo/Grey</name>
            </script>
            <ambient>1 1 1 1</ambient>
          </material>
          <meta>
            <layer>0</layer>
          </meta>
        </visual>
        <collision name='Wall_3_Collision_2'>
          <geometry>
            <box>
              <size>0.9 0.15 0.5</size>
            </box>
          </geometry>
          <pose>-0.164106 0 2.25 0 -0 0</pose>
          <max_contacts>10</max_contacts>
          <surface>
            <contact>
              <ode/>
            </contact>
            <bounce/>
            <friction>
              <torsional>
                <ode/>
              </torsional>
              <ode/>
            </friction>
          </surface>
        </collision>
        <self_collide>0</self_collide>
        <enable_wind>0</enable_wind>
        <kinematic>0</kinematic>
      </link>
      <link name='Wall_4'>
        <collision name='Wall_4_Collision'>
          <geometry>
            <box>
              <size>5.75 0.15 2.5</size>
            </box>
          </geometry>
          <pose>0 0 1.25 0 -0 0</pose>
          <max_contacts>10</max_contacts>
          <surface>
            <contact>
              <ode/>
            </contact>
            <bounce/>
            <friction>
              <torsional>
                <ode/>
              </torsional>
              <ode/>
            </friction>
          </surface>
        </collision>
        <visual name='Wall_4_Visual'>
          <pose>0 0 1.25 0 -0 0</pose>
          <geometry>
            <box>
              <size>5.75 0.15 2.5</size>
            </box>
          </geometry>
          <material>
            <script>
              <uri>file://media/materials/scripts/gazebo.material</uri>
              <name>Gazebo/Grey</name>
            </script>
            <ambient>1 1 1 1</ambient>
          </material>
          <meta>
            <layer>0</layer>
          </meta>
        </visual>
        <pose>-1.8 0 0 0 -0 -1.5708</pose>
        <self_collide>0</self_collide>
        <enable_wind>0</enable_wind>
        <kinematic>0</kinematic>
      </link>
      <static>1</static>
    </model>
    <state world_name='default'>
      <sim_time>71 791000000</sim_time>
      <real_time>73 449944628</real_time>
      <wall_time>1709804006 701094540</wall_time>
      <iterations>71791</iterations>
      <model name='Untitled'>
        <pose>0.26 -0.99 0 0 -0 0</pose>
        <scale>1 1 1</scale>
        <link name='Wall_1'>
          <pose>0.26 -3.79 0 0 -0 0</pose>
          <velocity>0 0 0 0 -0 0</velocity>
          <acceleration>0 0 0 0 -0 0</acceleration>
          <wrench>0 0 0 0 -0 0</wrench>
        </link>
        <link name='Wall_2'>
          <pose>2.06 -0.99 0 0 -0 1.5708</pose>
          <velocity>0 0 0 0 -0 0</velocity>
          <acceleration>0 0 0 0 -0 0</acceleration>
          <wrench>0 0 0 0 -0 0</wrench>
        </link>
        <link name='Wall_3'>
          <pose>0.26 1.81 0 0 -0 3.14159</pose>
          <velocity>0 0 0 0 -0 0</velocity>
          <acceleration>0 0 0 0 -0 0</acceleration>
          <wrench>0 0 0 0 -0 0</wrench>
        </link>
        <link name='Wall_4'>
          <pose>-1.54 -0.99 0 0 0 -1.5708</pose>
          <velocity>0 0 0 0 -0 0</velocity>
          <acceleration>0 0 0 0 -0 0</acceleration>
          <wrench>0 0 0 0 -0 0</wrench>
        </link>
      </model>
      <model name='ground_plane'>
        <pose>0 0 0 0 -0 0</pose>
        <scale>1 1 1</scale>
        <link name='link'>
          <pose>0 0 0 0 -0 0</pose>
          <velocity>0 0 0 0 -0 0</velocity>
          <acceleration>0 0 0 0 -0 0</acceleration>
          <wrench>0 0 0 0 -0 0</wrench>
        </link>
      </model>
      <model name='mobile_manipulator'>
        <pose>-0.05049 -0.000232 -0.005087 1.3e-05 6e-06 -0.009849</pose>
        <scale>1 1 1</scale>
        <link name='front_left_wheel'>
          <pose>-0.352083 -0.160453 0.074914 -0.121227 9e-06 -0.009847</pose>
          <velocity>-0.00194 0.001231 0.007757 -0.015002 0.00676 0.003304</velocity>
          <acceleration>-3.32624 2.66139 14.9105 1.38786 0.336213 -1.13295</acceleration>
          <wrench>-9.92938 7.9447 44.5104 0 -0 0</wrench>
        </link>
        <link name='front_right_wheel'>
          <pose>0.247888 -0.166362 0.074915 0.120218 -6e-06 -0.009849</pose>
          <velocity>-0.001934 0.001798 0.004484 0.443982 -0.007 0.000589</velocity>
          <acceleration>-3.33565 2.4282 10.6326 -1.7457 -1.27716 -0.704865</acceleration>
          <wrench>-9.95748 7.24858 31.7402 0 -0 0</wrench>
        </link>
        <link name='ground'>
          <pose>-0.05049 -0.000232 -0.005087 1.3e-05 6e-06 -0.009849</pose>
          <velocity>-0.002268 0.001852 0.006334 0.002899 0.002825 0.000618</velocity>
          <acceleration>0.104293 -0.075811 8.37435 -1.42507 0.661996 -0.701102</acceleration>
          <wrench>49.2203 -35.7786 3952.2 0 -0 0</wrench>
        </link>
        <link name='rear_left_wheel'>
          <pose>-0.362558 -1.22404 0.074915 -0.217429 3.5e-05 -0.009849</pose>
          <velocity>-0.001242 0.001424 0.005734 0.026712 0.008949 0.00061</velocity>
          <acceleration>-4.00804 2.86479 14.2008 2.46802 -1.4129 2.45995</acceleration>
          <wrench>-11.9647 8.5519 42.3917 0 -0 0</wrench>
        </link>
        <link name='rear_right_wheel'>
          <pose>0.237412 -1.22995 0.074914 0.217061 -2.9e-05 -0.009849</pose>
          <velocity>-0.001261 0.001803 0.001365 -0.228052 -0.050048 0.000708</velocity>
          <acceleration>-4.00853 2.45072 1.40453 -3.1391 -1.01504 -0.510034</acceleration>
          <wrench>-11.9661 7.31581 4.19277 0 -0 0</wrench>
        </link>
      </model>
      <light name='sun'>
        <pose>0 0 10 0 -0 0</pose>
      </light>
    </state>
    <gui fullscreen='0'>
      <camera name='user_camera'>
        <pose>0.644922 -0.163966 8.48629 -7e-06 1.5698 1.60019</pose>
        <view_controller>orbit</view_controller>
        <projection_type>perspective</projection_type>
      </camera>
    </gui>
  </world>
</sdf>
